Workbook

Sheet Raw_Data
A1: Student_ID | B1: Student_Name | C1: Gender | D1: Class_Section | E1: Maths_Marks | F1: Science_Marks | G1: English_Marks | H1: Attendance_Percent | I1: Study_Hours_Per_Day | J1: Performance_Category
A2: STU001 | B2: Aarav Sharma | C2: Female | D2: BCA-C | E2: 55 | F2: 66 | G2: 81 | H2: 72 | I2: 3.6 | J2: =IF(AVERAGE(E2:G2)>=75, "High",IF(AVERAGE(E2:G2)>=50,"Medium","Low")) -> Medium
A3: STU002 | B3: Ananya Verma | C3: Male | D3: BCA-C | E3: 84 | F3: 77 | G3: 87 | H3: 81 | I3: 1.9 | J3: =IF(AVERAGE(E3:G3)>=75, "High",IF(AVERAGE(E3:G3)>=50,"Medium","Low")) -> High
A4: STU003 | B4: Rohan Gupta | C4: Male | D4: BCA-B | E4: 69 | F4: 60 | G4: 58 | H4: 74 | I4: 3.2 | J4: =IF(AVERAGE(E4:G4)>=75, "High",IF(AVERAGE(E4:G4)>=50,"Medium","Low")) -> Medium
A5: STU004 | B5: Priya Singh | C5: Male | D5: BCA-B | E5: 61 | F5: 73 | G5: 70 | H5: 93 | I5: 2.6 | J5: =IF(AVERAGE(E5:G5)>=75, "High",IF(AVERAGE(E5:G5)>=50,"Medium","Low")) -> Medium
A6: STU005 | B6: Kabir Yadav | C6: Male | D6: BCA-A | E6: 66 | F6: 65 | G6: 79 | H6: 85 | I6: 5.2 | J6: =IF(AVERAGE(E6:G6)>=75, "High",IF(AVERAGE(E6:G6)>=50,"Medium","Low")) -> Medium
A7: STU006 | B7: Meera Mishra | C7: Male | D7: BCA-A | E7: 65 | F7: 67 | G7: 64 | H7: 80 | I7: 1.9 | J7: =IF(AVERAGE(E7:G7)>=75, "High",IF(AVERAGE(E7:G7)>=50,"Medium","Low")) -> Medium
A8: STU007 | B8: Arjun Patel | C8: Male | D8: BCA-C | E8: 82 | F8: 76 | G8: 79 | H8: 84 | I8: 2.9 | J8: =IF(AVERAGE(E8:G8)>=75, "High",IF(AVERAGE(E8:G8)>=50,"Medium","Low")) -> High
A9: STU008 | B9: Isha Khan | C9: Male | D9: BCA-A | E9: 53 | F9: 72 | G9: 51 | H9: 84 | I9: 3.5 | J9: =IF(AVERAGE(E9:G9)>=75, "High",IF(AVERAGE(E9:G9)>=50,"Medium","Low")) -> Medium
A10: STU009 | B10: Vivaan Joshi | C10: Female | D10: BCA-A | E10: 57 | F10: 76 | G10: 80 | H10: 95 | I10: 1.8 | J10: =IF(AVERAGE(E10:G10)>=75, "High",IF(AVERAGE(E10:G10)>=50,"Medium","Low")) -> Medium
A11: STU010 | B11: Sana Ali | C11: Male | D11: BCA-B | E11: 63 | F11: 80 | G11: 68 | H11: 88 | I11: 3.7 | J11: =IF(AVERAGE(E11:G11)>=75, "High",IF(AVERAGE(E11:G11)>=50,"Medium","Low")) -> Medium
A12: STU011 | B12: Aditya Tiwari | C12: Male | D12: BCA-C | E12: 70 | F12: 78 | G12: 65 | H12: 71 | I12: 1.8 | J12: =IF(AVERAGE(E12:G12)>=75, "High",IF(AVERAGE(E12:G12)>=50,"Medium","Low")) -> Medium
A13: STU012 | B13: Kavya Rao | C13: Male | D13: BCA-C | E13: 65 | F13: 71 | G13: 70 | H13: 87 | I13: 2.5 | J13: =IF(AVERAGE(E13:G13)>=75, "High",IF(AVERAGE(E13:G13)>=50,"Medium","Low")) -> Medium
... A101: STU100 | B101: Sana Ali | C101: Female | D101: BCA-C | E101: 50 | F101: 70 | G101: 71 | H101: 84 | I101: 2.5 | J101: =IF(AVERAGE(E101:G101)>=75, "High",IF(AVERAGE(E101:G101)>=50,"Medium","Low")) -> Medium

Sheet Analysis
A1: student performance analysis
A2: metric | B2: Maths_Marks | C2: Science_Marks | D2: English_Marks
A3: Average | B3: =AVERAGE(Raw_Data!E2:E101) -> 68.5 | C3: =AVERAGE(Raw_Data!F2:F101) -> 70.51 | D3: =AVERAGE(Raw_Data!G2:G101) -> 69.04
A4: Highest Marks | B4: =MAX(Raw_Data!E2:E101) -> 100 | C4: =MAX(Raw_Data!F2:F101) -> 96 | D4: =MAX(Raw_Data!G2:G101) -> 100
A5: Lowest Marks | B5: =MIN(Raw_Data!E2:E101) -> 25 | C5: =MIN(Raw_Data!F2:F101) -> 38 | D5: =MIN(Raw_Data!G2:G101) -> 38
A7: Other Performance Metrics
A8: Average Attendance | B8: =AVERAGE(Raw_Data!H2:H101) -> 81.53
A9: Average Study Hours | B9: =AVERAGE(Raw_Data!I2:I101) -> 2.646
A11: Key Findings
A12: Average Attendance is 82%
A13: Average daily study time is approximately 2.65 hours
A14: Subject-wise average marks are shown in the chart
A16: Attendance vs Maths Analysis
A17: Correilation | B17: =CORREL(Raw_Data!H2:H101,Raw_Data!E2:E101) -> -0.011455419
A18: Interpretation | B18: Attendance and Maths marks show almost no inear correlation in this dataset
A20: Study Hours vs Maths Analysis
A21: Correlation | B21: =CORREL(Raw_Data!I2:I101,Raw_Data!E2:E101) -> 0.35542425
A22: Interpretation | B22: Study hours and Maths marks show a positive correlation in this dataset
A24: Performance Summary
A25: Category | B25: Student Count
A26: High | B26: =COUNTIF(Raw_Data!J2:J101,"High") -> 34
A27: Medium | B27: =COUNTIF(Raw_Data!J2:J101,"Medium") -> 59
A28: Low | B28: =COUNTIF(Raw_Data!J2:J101,"Low") -> 7
A30: Final Insights
A31: Total students analyzed :100
A32: Average attendance:82%
A33: Average daily study time: 2.65 hours
A34: High performancce: 34students
A35: Medium performance: 59 students
A36: Low performance: 7 students
A37: Study hours and maths marks show a positive correlation
A39: Research Questions
A40: Which subject has the highest average marks? | B40: Compare maths,scienceand englishh average marks
A41: Is study time associated with maths marks? | B41: Correlation is approximately 0.355,indicating a positivve elationship
A42: Is attendance associated with maths marks? | B42: Correlation is apprimately -0.011,indicating almost no linear relationship
A43: How are students distributed across performance categories? | B43: High: 34, Medium: 59, Low: 7
A45: Hypothesis Testing
A46: Null Hypothesis | B46: Study hours have no significant linear relationship with maths marks
A47: Alternative Hypothesis | B47: Study hours have a significant linear relationship with maths marks
A48: t-statistic | B48: =0.355424249*SQRT((100-2)/(1-0.355424249^2)) -> 3.7643109
...

Sheet Data_Dictionary
A1: Column_Name | B1: Meaning | C1: Data_Type | D1: Notes
A2: Student_ID | B2: Unique student identifier | C2: Text | D2: STU001, STU002, ...
A3: Student_Name | B3: Student's display name | C3: Text | D3: Names; inspect extra spaces/duplicates
A4: Gender | B4: Reported gender category | C4: Category | D4: Female / Male
A5: Class_Section | B5: Student's class section | C5: Category | D5: BCA-A / BCA-B / BCA-C
A6: Maths_Marks | B6: Marks in Maths out of 100 | C6: Numeric | D6: 25–100; contains a missing value
A7: Science_Marks | B7: Marks in Science out of 100 | C7: Numeric | D7: 25–100; contains a missing value
A8: English_Marks | B8: Marks in English out of 100 | C8: Numeric | D8: 25–100; contains a missing value
A9: Attendance_Percent | B9: Attendance percentage | C9: Numeric | D9: 52–100; contains a missing value
A10: Study_Hours_Per_Day | B10: Average daily study hours | C10: Numeric | D10: 0.5–6.5 hours
